Workbook

Sheet Test cases
A1: TesTCASE ID | B1: Test Cases Title / Objective | C1: Env | D1: Pre-condition | E1: Steps | F1: Test Data | G1: Expected Results | H1: Post Cond | I1: TC Status | J1: Valid\invalid | K1: Attachment | L1: Requirement ID | M1: Type | N1: Tester
A2: TC_SIGNUP_001 | B2: Verify user can register with valid inputs | C2: Chrome v27+ | D2: Open the URL: User is on Sign Up page | E2: Create User account : 1- Enter username 2- enter email (20–50 chars) 3- Enter password (more than 8 less than 16) 4- Click Sign Up Delete the created account : 5- signup with admin account 6- go to manage users 7- press delete account | F2: 1- Username: yaranasser 2- Email: yaranasser1665@gmail.com 3- Password: 0123456@Yara | G2: User is registered successfully and redirected to Home page | H2: Account is created User is redirected to Home page Delete the created account | I2: Pass | J2: Valid | L2: SRS_SignUp_001 SRS_SignUp_011 | M2: Functional | N2: yara
A3: TC_SIGNUP_002 | B3: Check username placeholder exists | C3: Chrome v27+ | D3: Open the URL: User is on Sign Up page | E3: 1- Navigate to Sign Up page 2- Observe Username field | F3: N/A | G3: Username field displays a placeholder (e.g., "Choose a username (letters,numbers,spaces,special chars)") | H3: Field remains unchanged | I3: Pass | J3: Valid | L3: SRS_SignUp_002 | M3: UI | N3: yara
A4: TC_SIGNUP_003 | B4: Verify username is unique | C4: Chrome v27+ | D4: Open the URL: User is on Sign Up page | E4: 1- Enter used username 2- enter email (20–50 chars) 3- Enter password (8–16 chars with uppercase & special char) 4- Click Sign Up | F4: 1- Username: yaranasser 2- Email: yaranasser123@gmail.com 3- Password: 0147852@Yara | G4: User is can't register and and error message appears "Username already taken." | H4: Account is not created User remains in the signup page | I4: Pass | J4: Valid | L4: SRS_SignUp_003 | M4: Functional | N4: yara
A5: TC_SIGNUP_004 | B5: Verify username accepts special characters | C5: Chrome v27+ | D5: Open the URL: User is on Sign Up page | E5: Create User account : 1- Enter username 2- enter email (20–50 chars) 3- Enter password (more than 8 less than 16) 4- Click Sign Up Delete the created account : 5- signup with admin account 6- go to manage users 7- press delete account | F5: User account 1- Username:yara@ 2- Email: yaranasser123@gmail.com 3- Password: 0123456@Yara Admin account 1- admin 2- Admin@123 | G5: System accepts username and completes registration | H5: Account is created User is redirected to Home page Delete the created account : - signup with admin account - go to manage users - press delete account | I5: Pass | J5: Valid | L5: SRS_SignUp_004 | M5: Functional | N5: yara
A6: TC_SIGNUP_005 | B6: Verify username accepts numbers | C6: Chrome v27+ | D6: Open the URL: User is on Sign Up page | E6: Create User account : 1- Enter username 2- enter email (20–50 chars) 3- Enter password (more than 8 less than 16) 4- Click Sign Up Delete the created account : 5- signup with admin account 6- go to manage users 7- press delete account | F6: User account 1- Username:yara123 2- Email: yaranasser123@gmail.com 3- Password: 0123456@Yara Admin account 1- admin 2- Admin@123 | G6: System accepts username and completes registration | H6: Account is created User is redirected to Home page Delete the created account : - signup with admin account - go to manage users - press delete account | I6: Pass | J6: Valid | L6: SRS_SignUp_005 | M6: Functional | N6: yara
A7: TC_SIGNUP_006 | B7: Verify username accepts spaces | C7: Chrome v27+ | D7: Open the URL: User is on Sign Up page | E7: Create User account : 1- Enter username 2- enter email (20–50 chars) 3- Enter password (more than 8 less than 16) 4- Click Sign Up Delete the created account : 5- signup with admin account 6- go to manage users 7- press delete account | F7: User account 1- Username:yara ynn 2- Email: yaranasser123@gmail.com 3- Password: 0123456@Yara Admin account 1- admin 2- Admin@123 | G7: System accepts username with spaces | H7: Account is created User is redirected to Home page Delete the created account : - signup with admin account - go to manage users - press delete account | I7: Pass | J7: Valid | L7: SRS_SignUp_006 | M7: Functional | N7: yara
A8: TC_SIGNUP_007 | B8: Verify valid email length when it is between 20 and 50 characters | C8: Chrome v27+ | D8: Open the URL: User is on Sign Up page | E8: Create User account : 1- Enter username 2- enter email (20–50 chars) 3- Enter password (more than 8 less than 16) 4- Click Sign Up Delete the created account : 5- signup with admin account 6- go to manage users 7- press delete account | F8: User account 1- Username:yaranasser 2- Email: yaranasser123@gmail.com 3- Password: 0123456@Yara Admin account 1- admin 2- Admin@123 | G8: System accepts inputs data and directed to the home page | H8: Account is created User is redirected to Home page Delete the created account : - signup with admin account - go to manage users - press delete account | I8: Pass | J8: Valid | L8: SRS_SignUp_007 | M8: Functional | N8: yara
A9: TC_SIGNUP_008 | B9: Verify invalid email length when it is more than 50 characters | C9: Chrome v27+ | D9: Open the URL: User is on Sign Up page | E9: 1- Enter username 2- enter email (more than 50) 3- Enter password (8–16 chars with uppercase & special char) 4- Click Sign Up | F9: User account 1- Username:yaranasserr 2- Email: yaranasseryaranasser166666666666666666666665@gmail.com@gmail.com 3- Password: 0123456@Yara | G9: System rejects both inputs and shows error("Email must not exceed 50 characters") | H9: Account is NOT created User remains on Sign Up page Error message is displayed | I9: Pass | J9: Invalid | L9: SRS_SignUp_007 | M9: Functional | N9: yara
A10: TC_SIGNUP_009 | B10: Verify invalid email length when it is less than 20 characters | C10: Chrome v27+ | D10: Open the URL: User is on Sign Up page | E10: 1- Enter username 2- enter email (less than 20) 3- Enter password (8–16 chars with uppercase & special char) 4- Click Sign Up | F10: User account 1- Username:yaranasserr 2- Email: yn@gmail.com 3- Password: 0123456@Yara | G10: System rejects both inputs and shows error("Email must be at least 20 characters") | H10: Account is NOT created User remains on Sign Up page Error message is displayed | I10: Pass | J10: Invalid | L10: SRS_SignUp_007 | M10: Functional | N10: yara
A11: TC_SIGNUP_010 | B11: Verify valid password length when it is more than 8 and less than 16 characters | C11: Chrome v27+ | D11: Open the URL: User is on Sign Up page | E11: Create User account : 1- Enter username 2- enter email (20–50 chars) 3- Enter password (more than 8 less than 16) 4- Click Sign Up Delete the created account : 5- signup with admin account 6- go to manage users 7- press delete account | F11: User account 1- Username:yaranasser 2- Email: yaranasser123@gmail.com 3- Password: 0123456@Yara Admin account 1- admin 2- Admin@123 | G11: System accepts valid lengths Account is created User directed to home page | H11: Account is created User is redirected to Home page Delete the created account | I11: Pass | J11: Valid | L11: SRS_SignUp_008 | M11: Functional | N11: yara
A12: TC_SIGNUP_011 | B12: Verify invalid password length when it is more than 16 characters | C12: Chrome v27+ | D12: Open the URL: User is on Sign Up page | E12: 1- Enter username 2- enter email (20–80 chars) 3- Enter password (more than 16) 4- Click Sign Up | F12: User account 1- Username:yaranasser 2- Email: yaranasser123@gmail.com 3- Password: 0123456@Yaraaaaaaaaaaaaaaaaaaaaaaaaaaaa | G12: System rejects invalid lengths("Password must not exceed 16 characters") Account is NOT created User remains on Sign Up page Error message is displayed | H12: Account is NOT created User remains on Sign Up page Error message is displayed | I12: Pass | J12: Invalid | L12: SRS_SignUp_008 | M12: Functional | N12: yara
A13: TC_SIGNUP_012 | B13: Verify invalid password length when it is less than 8 | C13: Chrome v27+ | D13: Open the URL: User is on Sign Up page | E13: 1- Enter username 2- enter email (20–50 chars) 3- Enter password (less than 8) 4- Click Sign Up | F13: User account 1- Username:yaranasser 2- Email: yaranasser123@gmail.com 3- Password: yn | G13: System rejects invalid lengths("Password must not exceed 8 characters") Account is NOT created User remains on Sign Up page Error message is displayed | H13: Account is NOT created User remains on Sign Up page Error message is displayed | I13: Pass | J13: Invalid | L13: SRS_SignUp_008 | M13: Functional | N13: yara
... A21: TC-LOGIN-06 | B21: Verify System Rejects Incorrect Credentials | C21: Chrome v27+ | D21: user is on login page | E21: 1. Enter a wrong Username or non-existent Email. 2. Enter an incorrect Password. 3. Click the "Log in" button. | F21: Username: zainab OR Email: zainab@learninghub.com Password: zainab@99 | G21: System blocks login. Error message displayed: "Invalid Username or Password." | H21: User remains on Login page. No session created. | I21: In review | J21: Invalid | L21: SRS_Login_06 | M21: Functional | N21: Zainab
A22: TC-CAT-01 | B22: Verify visibility of the 4 main categories | C22: Chrome v27+ | D22: user is on home page | E22: observe the main interface | F22: for admin: userName: 'admin', email: 'admin@learninghub.com', password: 'Admin@123', for user: userName: 'user1', email: 'user1@learninghub.com', password: 'User@123', | G22: Home page clearly displays the main 4 categories | I22: In review | J22: Valid | L22: SRS-Category-01 | M22: UI | N22: shreen
A23: TC-CAT-02 | B23: Verify notifications for new content in followed categories | C23: Chrome v27+ | D23: user follows at least one category | E23: 1-login 2-Admin publishes new content in the followed category | F23: login using for admin: userName: 'admin', email: 'admin@learninghub.com', password: 'Admin@123', for user: userName: 'user1', email: 'user1@learninghub.com', password: 'User@123', New content:video/article/record | G23: System triggers apop-up notification | H23: Notification displayed | I23: In review | J23: Valid | L23: SRS-Category-02 | M23: Functional | N23: shreen
A24: TC-CAT-03 | B24: Verify "Empty state"message for categories with no data | C24: Chrome v27+ | D24: user is logged in | E24: 1-Click on a category that has no articles or videos | F24: login using for admin: userName: 'admin', email: 'admin@learninghub.com', password: 'Admin@123', for user: userName: 'user1', email: 'user1@learninghub.com', password: 'User@123', New content:video/article/record | G24: System displayes "No content yet" | H24: user stays on category page | I24: In review | J24: Valid | L24: SRS-Category-03 | M24: Functional | N24: shreen
A25: TC-LOUGOUT_01 | B25: Verify logout confirmation pop-up appearance | C25: Chrome v27+ | D25: user is logged in | E25: 1-Click on "Logout"button | F25: N/A | G25: Verify that a confirmation pop-up appears with the message "Are you sure you want to logout?" | H25: Session ended | I25: In review | J25: Valid | L25: SRS_Logout_01 | M25: Functional | N25: shreen
A26: TC-LOUGOUT_02 | B26: Verify successful logout execution and redirection | C26: Chrome v27+ | D26: user is logged in | E26: 1- Click "Logout" 2- Click [Confirm] on pop-up | F26: N/A | G26: Verify that the active session ends immediately and the system redirects the user to the Login Page. | H26: logout message visible | I26: In review | J26: Valid | L26: SRS_Logout_02 | M26: Functional | N26: shreen
A27: TC-LOUGOUT_03 | B27: Verify logout cancellation and session stability | C27: Chrome v27+ | D27: user is logged in | E27: 1-Click on "Logout"button 2-Click [Cancel] on pop-up. | F27: N/A | G27: The pop-up closes immediately, the active session remains valid | I27: In review | J27: Valid | L27: SRS_Logout_03 | M27: Functional | N27: shreen
A28: TC-UserFeatures-01 | B28: Verify user can navigate between categories | C28: Chrome v27+ | D28: 1- User has a registered account 2- User is logged in and on homepage | E28: 1-Navigate to the Home Page 2-Click on "Science" 3- Click on "Arts" 4- Click on "History" 5- Click on "AI" | F28: N/A | G28: System navigates to selected category Selected category is highlighted | H28: User remains on selected category page | I28: In review | J28: Valid | L28: SRS_UserFeature_01 | M28: UI / Functional | N28: Mohamed Khedr
A29: TC-UserFeatures-02 | B29: Verify user can follow a category | C29: Chrome v27+ | D29: 1- User has a registered account 2- User is logged in | E29: 1-Navigate to the Home Page 2- Click on "Follow" button on certain category | F29: N/A | G29: Category added to Followed List Button changes to "Followed" Pop-up: "Category followed successfully" | H29: Category appears in followed list | I29: In review | J29: Valid | L29: SRS_UserFeature_02 | M29: Functional | N29: Mohamed Khedr
A30: TC-UserFeatures-03 | B30: Verify notification popup appears for new content | C30: Chrome v27+ | D30: 1- User has a registered account 2- User is logged in 3-User followed any category before | E30: 1- Publish new article in folowed category from the second user 2- Check notification from the first user | F30: N/A | G30: User receives Popup notification with the name of topic for the published article contain (Article title - Category name) | H30: Notification is displayed to the user successfully | I30: In review | J30: Valid | L30: SRS_UserFeature_03 | M30: UI / Functional | N30: Mohamed Khedr
A31: TC-UserFeatures-04 | B31: Verify user can publish article with valid data | C31: Chrome v27+ | D31: 1- User has a registered account 2- User is logged in | E31: 1- Navigate to Home Page 2- Click on any category from the top menu 3-Click on publish article button 4- Enter Title 5- Enter Content 6- Click on "Publish" | F31: Title: "Introduction to Artificial Intelligence" Content: "Artificial Intelligence is a branch of computer science..." | G31: Article is published successfully Pop-up Message : "Article published successfully" | H31: Article is stored in the system database Article appears in the selected category list Article is visible to other users | I31: In review | J31: Valid | L31: SRS_UserFeature_04 | M31: Functional | N31: Mohamed Khedr
A32: TC-UserFeatures-05 | B32: Validate publishing article with empty title and content | C32: Chrome v27+ | D32: 1- User has a registered account 2- User is logged in 3- user is on Publish Article page | E32: 1- Navigate to Home Page 2- Click on any category from the top menu 3-Click on upload Article button 4- Leave Title field empty 5- Leave Content field empty 6- Click on "Upload" | F32: Title: "" (Empty) Content: "" (Empty) | G32: System prevents publishing the article Error Pop-Up message is displayed: "Title and Content are required" No article is created or stored | H32: No data is saved in the database User remains on the Publish page Input fields remain empty User can re-enter valid data | I32: In review | J32: Valid | L32: SRS_UserFeature_04 | M32: Negative | N32: Mohamed Khedr
A33: TC-UserFeatures-06 | B33: Upload valid video | C33: Chrome v27+ | D33: 1- User has a registered account 2- User is logged in 3- user is on Upload Video page | E33: 1- Navigate to Home Page 2- Click on any category from the top menu 3-Click on upload Video button 4- Select MP4 file 5- Click Confirm Upload | F33: File: video.mp4 Format: MP4 Size: 10MB | G33: Video is uploaded successfully Message: "Video uploaded successfully" Video is playable on the platform | H33: Video is stored in database/server Video appears in user content list Video is accessible to other users | I33: In review | J33: Valid | L33: SRS_UserFeature_05 | M33: Functional | N33: Mohamed Khedr
A34: TC-UserFeatures-07 | B34: Upload without selecting video | C34: Chrome v27+ | D34: 1- User has a registered account 2- User is logged in 3- user is on Upload Video page | E34: 1- Navigate to Home Page 2- Click on any category from the top menu 3-Click on upload Video button 4- Click Upload without selecting file 5- Click Confirm Upload | F34: N/A | G34: Upload is prevented Error: "Please select a video file" | H34: No file is uploaded User remains on same page System waits for valid input | I34: In review | J34: Valid | L34: SRS_UserFeature_05 | M34: Negative | N34: Mohamed Khedr
A35: TC-UserFeatures-08 | B35: Upload invalid file format | C35: Chrome v27+ | D35: 1- User has a registered account 2- User is logged in 3- user is on Upload Video page | E35: 1- Navigate to Home Page 2- Click on any category from the top menu 3-Click on upload Video button 4- Select file with format .txt or .jpg 5- Click Confirm Upload | F35: File: test.txt Format: TXT | G35: Upload is rejected Error: "Invalid file format" | H35: File is not stored User remains on upload page | I35: In review | J35: Valid | L35: SRS_UserFeature_05 | M35: Negative | N35: Mohamed Khedr
A36: TC-UserFeatures-09 | B36: Verify Post voice note successfully | C36: Chrome v27+ | D36: 1- User has a registered account 2- User is logged in 3- Microphone permission is allowed | E36: 1- Navigate to Home Page 2- Click on any category from the top menu 3-Click on Record button 4- Record voice note 5- Click Stop 6- Click Post | F36: Voice duration: 10 seconds Format: system default | G36: Voice note is posted Voice is playable Message: "Voice note posted successfully" | H36: Voice note is stored in system Appears in user content Accessible to others | I36: In review | J36: Valid | L36: SRS_UserFeature_06 | M36: Functional | N36: Mohamed Khedr
A37: TC-UserFeatures-10 | B37: Prevent empty voice note | C37: Chrome v27+ | D37: 1- User has a registered account 2- User is logged in | E37: 1- Navigate to Home Page 2- Click on any category from the top menu 3-Click on Record button 4- Click Post without recording | F37: N/A | G37: Post is prevented Error: "Voice note cannot be empty" | H37: No voice note is saved User remains on same page | I37: In review | J37: Valid | L37: SRS_UserFeature_06 | M37: Negative | N37: Mohamed Khedr
A38: TC-UserFeatures-11 | B38: Verify success messages appear correctly | C38: Chrome v27+ | D38: 1- User has a registered account 2- User is logged in 3- User has access to publish/upload features | E38: 1- Navigate to Home Page 2- Click on any category from the top menu 3-Publish article 4- Upload video 5- Post voice note | F38: Article: valid title + content Video: MP4 file Voice: recorded clip | G38: Success messages appear: "Article published successfully" "Video uploaded successfully" "Voice note posted successfully" | H38: All content is saved successfully Messages are displayed correctly No errors occur | I38: In review | J38: Valid | L38: SRS_UserFeature_07 | M38: Functional / UI | N38: Mohamed Khedr
A39: TC-UserFeatures-12 | B39: Verify user can delete own content | C39: Chrome v27+ | D39: 1- User has a registered account 2- User is logged in 3- User has already published content (article / video / voice note) | E39: 1- Navigate to Home Page 2- Go to user content (My Posts / Category) 3- Click on "Delete" button on user's own content 4- Confirm deletion | F39: N/A | G39: Content is deleted successfully Pop-Up Success Message: "Content deleted successfully" | H39: Content is removed from system Content no longer appears in content list | I39: In review | J39: Valid | L39: SRS_UserFeature_08 | M39: Functional | N39: Mohamed Khedr
... A42: TC-AdminFeatures-01 | B42: Verify admin can delete user account successfully | C42: Chrome v27+ | D42: 1- Admin has a valid account 2- Admin is logged in 3- There is an existing user account in the system | E42: 1- Navigate to Admin Dashboard 2- Go to manage users list 3- Click on "Delete account " button next to a user account 4- Confirm deletion | F42: account: shshluu | G42: User account is deleted successfully Success Pop-Up Message: "User account deleted successfully" | H42: User account is removed from the database User no longer appears in the system | I42: In review | J42: Valid | L42: SRS_AdminFeature_01 | M42: Functional | N42: Shreen
A43: TC-AdminFeatures-02 | B43: Verify user deletion cancellation | C43: Chrome v27+ | D43: 1- Admin has a valid account 2- Admin is logged in 3- There is an existing user account in the system | E43: 1- Click "Delete" next to a user. 2-Click [Cancel] on pop-up. | F43: account: shshluu | G43: System closes the pop-up immediately without deleting any data | I43: In review | J43: Valid | L43: SRS_AdminFeature_02 | M43: Functional | N43: Shreen
A44: TC-AdminFeatures-03 | B44: Verify error for non-existent user | C44: Chrome v27+ | D44: 1- Admin has a valid account 2- Admin is logged in | E44: Trigger deletion for a User ID which deleted recently | F44: account: shshluu | G44: System identifies that the account ID is missing and displays an error notification: "User account not found". | I44: Rejaected | J44: Invalid | L44: SRS_AdminFeature_02 | M44: Functional | N44: Shreen
A45: TC-AdminFeatures-04 | B45: Verify admin can delete any video successfully | C45: Chrome v27+ | D45: 1- Admin has a valid account 2- Admin is logged in 3- There is an existing video uploaded by any user | E45: 1- Navigate to Admin Dashboard 2- Go to Videos 3-Click on "see more details" 4- Click "Delete" on a Video. 5- Click [delete] on pop-up. | F45: username:admin password:Admin@123 an uploaded video | G45: Video is deleted successfully Success Pop-Up Message: "Content deleted successfully" | H45: Video is removed from the system Video no longer appears in the content list | I45: In review | J45: Valid | L45: SRS_AdminFeature_03 | M45: Functional | N45: Shreen
A46: TC-AdminFeatures-05 | B46: Verify admin can delete any article successfully | C46: Chrome v27+ | D46: 1- Admin has a valid account 2- Admin is logged in 3- There is an existing article created by any user | E46: 1- Navigate to Admin Dashboard 2- Go to content 3-Click on "see more details" 4- Click "Delete" on an article. 5- Click [delete] on pop-up. | F46: username:admin password:Admin@123 an uploaded video | G46: Article is deleted successfully Success Pop-Up Message: "Content deleted successfully" | H46: Article is removed from the system Article no longer appears in the system | I46: In review | J46: Valid | L46: SRS_AdminFeature_03 | M46: Functional | N46: Shreen
A47: TC-AdminFeatures-06 | B47: Verify admin can delete any voice note successfully | C47: Chrome v27+ | D47: 1- Admin has a valid account 2- Admin is logged in 3- There is an existing voice note created by any user | E47: 1- Navigate to Admin Dashboard 2- Go to content 3-Click on "see more details" 4- Click "Delete" 5- Click [delete] on pop-up. | F47: username:admin password:Admin@123 an uploaded video | G47: Voice note is deleted successfully Success Pop-Up Message: "Content deleted successfully" | H47: Voice note is removed from the system Voice note no longer appears in the system | I47: In review | J47: Valid | L47: SRS_AdminFeature_03 | M47: Functional | N47: Shreen
A48: TC-AdminFeatures-07 | B48: Verify content deletion cancellation | C48: Chrome v27+ | D48: Admin is logged in | E48: 1- Click "Delete" next to any content 2- When confirmation pop-up appears, click "Cancel | F48: username:admin password:Admin@123 | G48: System terminates the deletion process and ensures the selected content remains fully accessible and unchanged. | H48: the system remains unchanged | I48: In review | J48: Valid | L48: SRS_AdminFeature_04 | M48: Functional | N48: Shreen
C49: Chrome v27+ | D49: Admin is logged in

Sheet Execution V1
A1: TesTCASE ID | B1: Test Cases Title / Objective | C1: Env | D1: Pre-condition | E1: Steps | F1: Test Data | G1: Expected Results | H1: Post Cond | I1: TC Status | J1: Valid\invalid | K1: Attachment | L1: Requirement ID | M1: Type | N1: Tester | O1: Execution Status
A2: TC_SIGNUP_001 | B2: Verify user can register with valid inputs | C2: Chrome v27+ | D2: Open the URL: User is on Sign Up page | E2: Create User account : 1- Enter username 2- enter email (20–50 chars) 3- Enter password (more than 8 less than 16) 4- Click Sign Up Delete the created account : 5- signup with admin account 6- go to manage users 7- press delete account | F2: 1- Username: yaranasser 2- Email: yaranasser1665@gmail.com 3- Password: 0123456@Yara | G2: User is registered successfully and redirected to Home page | H2: Account is created User is redirected to Home page Delete the created account | I2: Pass | J2: Valid | L2: SRS_SignUp_001 SRS_SignUp_011 | M2: Functional | N2: yara | O2: Pass
A3: TC_SIGNUP_002 | B3: Check username placeholder exists | C3: Chrome v27+ | D3: Open the URL: User is on Sign Up page | E3: 1- Navigate to Sign Up page 2- Observe Username field | F3: N/A | G3: Username field displays a placeholder (e.g., "Choose a username (letters,numbers,spaces,special chars)") | H3: Field remains unchanged | I3: Pass | J3: Valid | L3: SRS_SignUp_002 | M3: UI | N3: yara | O3: Pass
A4: TC_SIGNUP_003 | B4: Verify username is unique | C4: Chrome v27+ | D4: Open the URL: User is on Sign Up page | E4: 1- Enter used username 2- enter email (20–50 chars) 3- Enter password (8–16 chars with uppercase & special char) 4- Click Sign Up | F4: 1- Username: yaranasser 2- Email: yaranasser123@gmail.com 3- Password: 0147852@Yara | G4: User is can't register and and error message appears "Username already taken." | H4: Account is not created User remains in the signup page | I4: Pass | J4: Valid | L4: SRS_SignUp_003 | M4: Functional | N4: yara | O4: Pass
A5: TC_SIGNUP_004 | B5: Verify username accepts special characters | C5: Chrome v27+ | D5: Open the URL: User is on Sign Up page | E5: Create User account : 1- Enter username 2- enter email (20–50 chars) 3- Enter password (more than 8 less than 16) 4- Click Sign Up Delete the created account : 5- signup with admin account 6- go to manage users 7- press delete account | F5: User account 1- Username:yara@ 2- Email: yaranasser123@gmail.com 3- Password: 0123456@Yara Admin account 1- admin 2- Admin@123 | G5: System accepts username and completes registration | H5: Account is created User is redirected to Home page Delete the created account : - signup with admin account - go to manage users - press delete account | I5: Pass | J5: Valid | L5: SRS_SignUp_004 | M5: Functional | N5: yara | O5: Pass
A6: TC_SIGNUP_005 | B6: Verify username accepts numbers | C6: Chrome v27+ | D6: Open the URL: User is on Sign Up page | E6: Create User account : 1- Enter username 2- enter email (20–50 chars) 3- Enter password (more than 8 less than 16) 4- Click Sign Up Delete the created account : 5- signup with admin account 6- go to manage users 7- press delete account | F6: User account 1- Username:yara123 2- Email: yaranasser123@gmail.com 3- Password: 0123456@Yara Admin account 1- admin 2- Admin@123 | G6: System accepts username and completes registration | H6: Account is created User is redirected to Home page Delete the created account : - signup with admin account - go to manage users - press delete account | I6: Pass | J6: Valid | L6: SRS_SignUp_005 | M6: Functional | N6: yara | O6: Pass
A7: TC_SIGNUP_006 | B7: Verify username accepts spaces | C7: Chrome v27+ | D7: Open the URL: User is on Sign Up page | E7: Create User account : 1- Enter username 2- enter email (20–50 chars) 3- Enter password (more than 8 less than 16) 4- Click Sign Up Delete the created account : 5- signup with admin account 6- go to manage users 7- press delete account | F7: User account 1- Username:yara ynn 2- Email: yaranasser123@gmail.com 3- Password: 0123456@Yara Admin account 1- admin 2- Admin@123 | G7: System accepts username with spaces | H7: Account is created User is redirected to Home page Delete the created account : - signup with admin account - go to manage users - press delete account | I7: Pass | J7: Valid | L7: SRS_SignUp_006 | M7: Functional | N7: yara | O7: Pass
A8: TC_SIGNUP_007 | B8: Verify valid email length when it is between 20 and 50 characters | C8: Chrome v27+ | D8: Open the URL: User is on Sign Up page | E8: Create User account : 1- Enter username 2- enter email (20–50 chars) 3- Enter password (more than 8 less than 16) 4- Click Sign Up Delete the created account : 5- signup with admin account 6- go to manage users 7- press delete account | F8: User account 1- Username:yaranasser 2- Email: yaranasser123@gmail.com 3- Password: 0123456@Yara Admin account 1- admin 2- Admin@123 | G8: System accepts inputs data and directed to the home page | H8: Account is created User is redirected to Home page Delete the created account : - signup with admin account - go to manage users - press delete account | I8: Pass | J8: Valid | L8: SRS_SignUp_007 | M8: Functional | N8: yara | O8: Pass
A9: TC_SIGNUP_008 | B9: Verify invalid email length when it is more than 50 characters | C9: Chrome v27+ | D9: Open the URL: User is on Sign Up page | E9: 1- Enter username 2- enter email (more than 50) 3- Enter password (8–16 chars with uppercase & special char) 4- Click Sign Up | F9: User account 1- Username:yaranasserr 2- Email: yaranasseryaranasser166666666666666666666665@gmail.com@gmail.com 3- Password: 0123456@Yara | G9: System rejects both inputs and shows error("Email must not exceed 50 characters") | H9: Account is NOT created User remains on Sign Up page Error message is displayed | I9: Pass | J9: Invalid | L9: SRS_SignUp_007 | M9: Functional | N9: yara | O9: Pass
A10: TC_SIGNUP_009 | B10: Verify invalid email length when it is less than 20 characters | C10: Chrome v27+ | D10: Open the URL: User is on Sign Up page | E10: 1- Enter username 2- enter email (less than 20) 3- Enter password (8–16 chars with uppercase & special char) 4- Click Sign Up | F10: User account 1- Username:yaranasserr 2- Email: yn@gmail.com 3- Password: 0123456@Yara | G10: System rejects both inputs and shows error("Email must be at least 20 characters") | H10: Account is NOT created User remains on Sign Up page Error message is displayed | I10: Pass | J10: Invalid | L10: SRS_SignUp_007 | M10: Functional | N10: yara | O10: Pass
A11: TC_SIGNUP_010 | B11: Verify valid password length when it is more than 8 and less than 16 characters | C11: Chrome v27+ | D11: Open the URL: User is on Sign Up page | E11: Create User account : 1- Enter username 2- enter email (20–50 chars) 3- Enter password (more than 8 less than 16) 4- Click Sign Up Delete the created account : 5- signup with admin account 6- go to manage users 7- press delete account | F11: User account 1- Username:yaranasser 2- Email: yaranasser123@gmail.com 3- Password: 0123456@Yara Admin account 1- admin 2- Admin@123 | G11: System accepts valid lengths Account is created User directed to home page | H11: Account is created User is redirected to Home page Delete the created account | I11: Pass | J11: Valid | L11: SRS_SignUp_008 | M11: Functional | N11: yara | O11: Pass
A12: TC_SIGNUP_011 | B12: Verify invalid password length when it is more than 16 characters | C12: Chrome v27+ | D12: Open the URL: User is on Sign Up page | E12: 1- Enter username 2- enter email (20–80 chars) 3- Enter password (more than 16) 4- Click Sign Up | F12: User account 1- Username:yaranasser 2- Email: yaranasser123@gmail.com 3- Password: 0123456@Yaraaaaaaaaaaaaaaaaaaaaaaaaaaaa | G12: System rejects invalid lengths("Password must not exceed 16 characters") Account is NOT created User remains on Sign Up page Error message is displayed | H12: Account is NOT created User remains on Sign Up page Error message is displayed | I12: Pass | J12: Invalid | L12: SRS_SignUp_008 | M12: Functional | N12: yara | O12: Pass
A13: TC_SIGNUP_012 | B13: Verify invalid password length when it is less than 8 | C13: Chrome v27+ | D13: Open the URL: User is on Sign Up page | E13: 1- Enter username 2- enter email (20–50 chars) 3- Enter password (less than 8) 4- Click Sign Up | F13: User account 1- Username:yaranasser 2- Email: yaranasser123@gmail.com 3- Password: yn | G13: System rejects invalid lengths("Password must not exceed 8 characters") Account is NOT created User remains on Sign Up page Error message is displayed | H13: Account is NOT created User remains on Sign Up page Error message is displayed | I13: Pass | J13: Invalid | L13: SRS_SignUp_008 | M13: Functional | N13: yara | O13: Pass
... A21: TC-LOGIN-06 | B21: Verify System Rejects Incorrect Credentials | C21: Chrome v27+ | D21: user is on login page | E21: 1. Enter a wrong Username or non-existent Email. 2. Enter an incorrect Password. 3. Click the "Log in" button. | F21: Username: zainab OR Email: zainab@learninghub.com Password: zainab@99 | G21: System blocks login. Error message displayed: "Invalid Username or Password." | H21: User remains on Login page. No session created. | I21: Pass | J21: Invalid | L21: SRS_Login_06 | M21: Functional | N21: Zainab | O21: Pass
A22: TC-CAT-01 | B22: Verify visibility of the 4 main categories | C22: Chrome v27+ | D22: user is on home page | E22: observe the main interface | F22: for admin: userName: 'admin', email: 'admin@learninghub.com', password: 'Admin@123', for user: userName: 'user1', email: 'user1@learninghub.com', password: 'User@123', | G22: Home page clearly displays the main 4 categories | I22: In review | J22: Valid | L22: SRS-Category-01 | M22: UI | N22: yara | O22: Fail
A23: TC-CAT-02 | B23: Verify notifications for new content in followed categories | C23: Chrome v27+ | D23: user follows at least one category | E23: 1-login 2-Admin publishes new content in the followed category | F23: login using for admin: userName: 'admin', email: 'admin@learninghub.com', password: 'Admin@123', for user: userName: 'user1', email: 'user1@learninghub.com', password: 'User@123', New content:video/article/record | G23: System triggers apop-up notification | H23: Notification displayed | I23: In review | J23: Valid | L23: SRS-Category-02 | M23: Functional | N23: yara | O23: Blocked
A24: TC-CAT-03 | B24: Verify "Empty state"message for categories with no data | C24: Chrome v27+ | D24: user is logged in | E24: 1-Click on a category that has no articles or videos | F24: login using for admin: userName: 'admin', email: 'admin@learninghub.com', password: 'Admin@123', for user: userName: 'user1', email: 'user1@learninghub.com', password: 'User@123', New content:video/article/record category with zero content | G24: System displayes "No content yet" | H24: user stays on category page | I24: In review | J24: Valid | L24: SRS-Category-03 | M24: Functional | N24: yara | O24: Fail
A26: TC-LOUGOUT_01 | B26: Verify that user can end active session via logout button | C26: Chrome v27+ | D26: user is logged in | E26: 1-Click on "Logout"button | F26: N/A | G26: System ends the session immediately | H26: Session ended | I26: In review | J26: Valid | L26: SRS_Logout_01 | M26: Functional | O26: Pass
A27: TC-LOUGOUT_02 | B27: Verify the logout confirmation message | C27: Chrome v27+ | D27: user is logged in | E27: 1-Click on "Logout"button | F27: N/A | G27: A clear pop-up message displays "You have been successfully logged out" | H27: logout message visible | I27: In review | J27: Valid | L27: SRS_Logout_02 | M27: Functional | O27: Fail
A29: TC-UserFeatures-01 | B29: Verify user can navigate between categories | C29: Chrome v27+ | D29: 1- User has a registered account 2- User is logged in and on homepage | E29: 1-Navigate to the Home Page 2-Click on "Science" 3- Click on "Arts" 4- Click on "History" 5- Click on "AI" | F29: N/A | G29: System navigates to selected category Selected category is highlighted | H29: User remains on selected category page | I29: Pass | J29: Valid | L29: SRS_UserFeature_01 | M29: UI / Functional | N29: Mohamed Khedr | O29: Pass
A30: TC-UserFeatures-02 | B30: Verify user can follow a category | C30: Chrome v27+ | D30: 1- User has a registered account 2- User is logged in | E30: 1-Navigate to the Home Page 2- Click on "Follow" button on certain category | F30: N/A | G30: Category added to Followed List Button changes to "Followed" Pop-up: "Category followed successfully" | H30: Category appears in followed list | I30: Pass | J30: Valid | L30: SRS_UserFeature_02 | M30: Functional | N30: Mohamed Khedr | O30: Pass
A31: TC-UserFeatures-03 | B31: Verify notification popup appears for new content | C31: Chrome v27+ | D31: 1- User has a registered account 2- User is logged in 3-User followed any category before | E31: 1- Publish new article in folowed category from the second user 2- Check notification from the first user | F31: N/A | G31: User receives Popup notification with the name of topic for the published article contain (Article title - Category name) | H31: Notification is displayed to the user successfully | I31: Pass | J31: Valid | L31: SRS_UserFeature_03 | M31: UI / Functional | N31: Mohamed Khedr | O31: Blocked
A32: TC-UserFeatures-04 | B32: Verify user can publish article with valid data | C32: Chrome v27+ | D32: 1- User has a registered account 2- User is logged in | E32: 1- Navigate to Home Page 2- Click on any category from the top menu 3-Click on publish article button 4- Enter Title 5- Enter Content 6- Click on "Publish" | F32: Title: "Introduction to Artificial Intelligence" Content: "Artificial Intelligence is a branch of computer science..." | G32: Article is published successfully Pop-up Message : "Article published successfully" | H32: Article is stored in the system database Article appears in the selected category list Article is visible to other users | I32: Pass | J32: Valid | L32: SRS_UserFeature_04 | M32: Functional | N32: Mohamed Khedr | O32: Blocked
A33: TC-UserFeatures-05 | B33: Validate publishing article with empty title and content | C33: Chrome v27+ | D33: 1- User has a registered account 2- User is logged in 3- user is on Publish Article page | E33: 1- Navigate to Home Page 2- Click on any category from the top menu 3-Click on upload Article button 4- Leave Title field empty 5- Leave Content field empty 6- Click on "Upload" | F33: Title: "" (Empty) Content: "" (Empty) | G33: System prevents publishing the article Error Pop-Up message is displayed: "Title and Content are required" No article is created or stored | H33: No data is saved in the database User remains on the Publish page Input fields remain empty User can re-enter valid data | I33: Pass | J33: Valid | L33: SRS_UserFeature_04 | M33: Negative | N33: Mohamed Khedr | O33: Fail
A34: TC-UserFeatures-06 | B34: Upload valid video | C34: Chrome v27+ | D34: 1- User has a registered account 2- User is logged in 3- user is on Upload Video page | E34: 1- Navigate to Home Page 2- Click on any category from the top menu 3-Click on upload Video button 4- Select MP4 file 5- Click Confirm Upload | F34: File: video.mp4 Format: MP4 Size: 10MB | G34: Video is uploaded successfully Message: "Video uploaded successfully" Video is playable on the platform | H34: Video is stored in database/server Video appears in user content list Video is accessible to other users | I34: Pass | J34: Valid | L34: SRS_UserFeature_05 | M34: Functional | N34: Mohamed Khedr | O34: Blocked
A35: TC-UserFeatures-07 | B35: Upload without selecting video | C35: Chrome v27+ | D35: 1- User has a registered account 2- User is logged in 3- user is on Upload Video page | E35: 1- Navigate to Home Page 2- Click on any category from the top menu 3-Click on upload Video button 4- Click Upload without selecting file 5- Click Confirm Upload | F35: N/A | G35: Upload is prevented Error: "Please select a video file" | H35: No file is uploaded User remains on same page System waits for valid input | I35: Pass | J35: Valid | L35: SRS_UserFeature_05 | M35: Negative | N35: Mohamed Khedr | O35: Fail
A36: TC-UserFeatures-08 | B36: Upload invalid file format | C36: Chrome v27+ | D36: 1- User has a registered account 2- User is logged in 3- user is on Upload Video page | E36: 1- Navigate to Home Page 2- Click on any category from the top menu 3-Click on upload Video button 4- Select file with format .txt or .jpg 5- Click Confirm Upload | F36: File: test.txt Format: TXT | G36: Upload is rejected Error: "Invalid file format" | H36: File is not stored User remains on upload page | I36: Pass | J36: Valid | L36: SRS_UserFeature_05 | M36: Negative | N36: Mohamed Khedr | O36: Blocked
A37: TC-UserFeatures-09 | B37: Verify Post voice note successfully | C37: Chrome v27+ | D37: 1- User has a registered account 2- User is logged in 3- Microphone permission is allowed | E37: 1- Navigate to Home Page 2- Click on any category from the top menu 3-Click on Record button 4- Record voice note 5- Click Stop 6- Click Post | F37: Voice duration: 10 seconds Format: system default | G37: Voice note is posted Voice is playable Message: "Voice note posted successfully" | H37: Voice note is stored in system Appears in user content Accessible to others | I37: Pass | J37: Valid | L37: SRS_UserFeature_06 | M37: Functional | N37: Mohamed Khedr | O37: Blocked
A38: TC-UserFeatures-10 | B38: Prevent empty voice note | C38: Chrome v27+ | D38: 1- User has a registered account 2- User is logged in | E38: 1- Navigate to Home Page 2- Click on any category from the top menu 3-Click on Record button 4- Click Post without recording | F38: N/A | G38: Post is prevented Error: "Voice note cannot be empty" | H38: No voice note is saved User remains on same page | I38: Pass | J38: Valid | L38: SRS_UserFeature_06 | M38: Negative | N38: Mohamed Khedr | O38: Fail
A39: TC-UserFeatures-11 | B39: Verify success messages appear correctly | C39: Chrome v27+ | D39: 1- User has a registered account 2- User is logged in 3- User has access to publish/upload features | E39: 1- Navigate to Home Page 2- Click on any category from the top menu 3-Publish article 4- Upload video 5- Post voice note | F39: Article: valid title + content Video: MP4 file Voice: recorded clip | G39: Success messages appear: "Article published successfully" "Video uploaded successfully" "Voice note posted successfully" | H39: All content is saved successfully Messages are displayed correctly No errors occur | I39: Pass | J39: Valid | L39: SRS_UserFeature_07 | M39: Functional / UI | N39: Mohamed Khedr | O39: Blocked
A40: TC-UserFeatures-12 | B40: Verify user can delete own content | C40: Chrome v27+ | D40: 1- User has a registered account 2- User is logged in 3- User has already published content (article / video / voice note) | E40: 1- Navigate to Home Page 2- Go to user content (My Posts / Category) 3- Click on "Delete" button on user's own content 4- Confirm deletion | F40: N/A | G40: Content is deleted successfully Pop-Up Success Message: "Content deleted successfully" | H40: Content is removed from system Content no longer appears in content list | I40: Pass | J40: Valid | L40: SRS_UserFeature_08 | M40: Functional | N40: Mohamed Khedr | O40: Blocked
... A46: TC-AdminFeatures-04 | B46: Verify admin can delete any voice note successfully | C46: Chrome v27+ | D46: 1- Admin has a valid account 2- Admin is logged in 3- There is an existing voice note created by any user | E46: Navigate to Admin Dashboard Go to Voice Notes List Locate a voice note created by any user Click on "Delete" button Confirm deletion | F46: N/A | G46: Voice note is deleted successfully Success Pop-Up Message: "Content deleted successfully" | H46: Voice note is removed from the system Voice note no longer appears in the system | I46: In review | J46: Valid | L46: SRS_AdminFeature_02 | M46: Functional | N46: Shreen | O46: Fail

Sheet Bug Report V1
A1: Defect_ID | B1: Defect Title/Issue | C1: Pre-condition | D1: Test Data | E1: (Test-Steps)procedures | F1: POST COND | G1: Expected Result | H1: Actual Result | I1: Attachment | J1: priority | K1: Probability | L1: Severity | M1: Categorization | N1: Test case ID | O1: Defect Status | P1: Req ID | Q1: Created by
A2: DF-CAT-01 | B2: Visibility of the 4 main categories is not available only 3 categories is visible | C2: user is on home page | J2: Medium | K2: High | L2: Low | M2: =LET( total_score, SUM( SWITCH(J2, "High", 3, "Medium", 2, "Low", 1, 0), SWITCH(K2, "High", 3, "Medium", 2, "Low", 1, 0), SWITCH(L2, "High", 3, "Medium", 2, "Low", 1, 0) ), IFS( total_score >= 8, "Critical", total_score >= 5, "Major", total_score < 5, "Minor" )) -> Major | O2: Closed
A3: DF-UserFreatures-01 | B3: Validation message of publishing article/video/record is generic | C3: 1- User has a registered account 2- User is logged in 3- user is on Publish Article page | D3: userName: 'user1', email: 'user1@learninghub.com', password: 'User@123' | E3: 1- Navigate to Home Page 2- Click on any category from the top menu 3-Click on upload Article button 4- Leave Title field empty 5- Leave Content field empty 6- Click on "Upload" | F3: No data is saved in the database User remains on the Publish page Input fields remain empty User can re-enter valid data | G3: System prevents publishing the article Error Pop-Up message is displayed: "Title and Content are required" No article is created or stored | H3: Error message is appeared "Required fields missing" | J3: Low | K3: Medium | L3: Low | M3: =LET( total_score, SUM( SWITCH(J3, "High", 3, "Medium", 2, "Low", 1, 0), SWITCH(K3, "High", 3, "Medium", 2, "Low", 1, 0), SWITCH(L3, "High", 3, "Medium", 2, "Low", 1, 0) ), IFS( total_score >= 8, "Critical", total_score >= 5, "Major", total_score < 5, "Minor" )) -> Minor | O3: Closed | P3: SRS_UserFeature_04 SRS_UserFeature_05 SRS_UserFeature_06 | Q3: Mohamed Khedr
O4: Closed
J5: Medium | K5: High | L5: Low | M5: =LET( total_score, SUM( SWITCH(J5, "High", 3, "Medium", 2, "Low", 1, 0), SWITCH(K5, "High", 3, "Medium", 2, "Low", 1, 0), SWITCH(L5, "High", 3, "Medium", 2, "Low", 1, 0) ), IFS( total_score >= 8, "Critical", total_score >= 5, "Major", total_score < 5, "Minor" )) -> Major | O5: Closed
A6: DF-Logout-01 | B6: Logout confirmation message not displayed after clicking logout | C6: User is logged into the system | D6: Valid logged-in user account | E6: 1- Click on "Logout" button | F6: User is logged out successfully | G6: A clear pop-up message displays: "You have been successfully logged out" | H6: User is logged out but no confirmation message is displayed | I6: N/A | J6: Medium | K6: High | L6: Low | M6: =LET( total_score, SUM( SWITCH(J6, "High", 3, "Medium", 2, "Low", 1, 0), SWITCH(K6, "High", 3, "Medium", 2, "Low", 1, 0), SWITCH(L6, "High", 3, "Medium", 2, "Low", 1, 0) ), IFS( total_score >= 8, "Critical", total_score >= 5, "Major", total_score < 5, "Minor" )) -> Major | O6: Closed | P6: SRS_Logout_02 | Q6: Zainab
A7: DF-AdminFeature-01 | B7: Delete button for videos is not visible in Admin Dashboard | C7: 1- Admin is logged in 2- There is an existing video uploaded | D7: Any existing video | E7: 1- Navigate to Admin Dashboard 2- Go to Videos / Content List 3- Try to locate delete button for any video | F7: N/A | G7: Each video should have a visible "Delete" button | H7: Delete button is not displayed for any video | J7: High | K7: High | L7: High | M7: =LET( total_score, SUM( SWITCH(J7, "High", 3, "Medium", 2, "Low", 1, 0), SWITCH(K7, "High", 3, "Medium", 2, "Low", 1, 0), SWITCH(L7, "High", 3, "Medium", 2, "Low", 1, 0) ), IFS( total_score >= 8, "Critical", total_score >= 5, "Major", total_score < 5, "Minor" )) -> Critical | O7: Closed | P7: TC-AdminFeatures-02 | Q7: Zainab
A8: DF-AdminFeature-02 | B8: Delete button for voice notes is not visible in Admin Dashboard | C8: 1- Admin is logged in 2- There is an existing voice note | D8: Any existing voice note | E8: 1- Navigate to Admin Dashboard 2- Go to Voice Notes List 3- Try to locate delete button | F8: N/A | G8: Each voice note should have a visible "Delete" button | H8: Delete button is not displayed for any voice note | J8: High | K8: High | L8: High | M8: =LET( total_score, SUM( SWITCH(J8, "High", 3, "Medium", 2, "Low", 1, 0), SWITCH(K8, "High", 3, "Medium", 2, "Low", 1, 0), SWITCH(L8, "High", 3, "Medium", 2, "Low", 1, 0) ), IFS( total_score >= 8, "Critical", total_score >= 5, "Major", total_score < 5, "Minor" )) -> Critical | O8: Closed | P8: TC-AdminFeatures-04 | Q8: Zainab
J9: Medium | K9: High | L9: Low | M9: =LET( total_score, SUM( SWITCH(J9, "High", 3, "Medium", 2, "Low", 1, 0), SWITCH(K9, "High", 3, "Medium", 2, "Low", 1, 0), SWITCH(L9, "High", 3, "Medium", 2, "Low", 1, 0) ), IFS( total_score >= 8, "Critical", total_score >= 5, "Major", total_score < 5, "Minor" )) -> Major | O9: Closed
J10: Medium | K10: High | L10: Low | M10: =LET( total_score, SUM( SWITCH(J10, "High", 3, "Medium", 2, "Low", 1, 0), SWITCH(K10, "High", 3, "Medium", 2, "Low", 1, 0), SWITCH(L10, "High", 3, "Medium", 2, "Low", 1, 0) ), IFS( total_score >= 8, "Critical", total_score >= 5, "Major", total_score < 5, "Minor" )) -> Major | O10: Closed
J11: Medium | K11: High | L11: Low | M11: =LET( total_score, SUM( SWITCH(J11, "High", 3, "Medium", 2, "Low", 1, 0), SWITCH(K11, "High", 3, "Medium", 2, "Low", 1, 0), SWITCH(L11, "High", 3, "Medium", 2, "Low", 1, 0) ), IFS( total_score >= 8, "Critical", total_score >= 5, "Major", total_score < 5, "Minor" )) -> Major | O11: Closed
J12: Medium | K12: High | L12: Low | M12: Major | O12: Closed
A13: DF-CAT-01 | B13: Visibility of the 4 main categories is not available only 3 categories is visible | C13: user is on home page | D13: for admin: userName: 'admin', email: 'admin@learninghub.com', password: 'Admin@123', for user: userName: 'user1', email: 'user1@learninghub.com', password: 'User@123', | E13: Tester observe the main interface | G13: Home page clearly displays the main 4 categories | H13: only 3 categories is visible | J13: Low | K13: High | L13: Medium | M13: =LET( total_score, SUM( SWITCH(J13, "High", 3, "Medium", 2, "Low", 1, 0), SWITCH(K13, "High", 3, "Medium", 2, "Low", 1, 0), SWITCH(L13, "High", 3, "Medium", 2, "Low", 1, 0) ), IFS( total_score >= 8, "Critical", total_score >= 5, "Major", total_score < 5, "Minor" )) -> Major | N13: TC-CAT-01 | O13: Closed | P13: SRS_Category_01 | Q13: yara
A14: DF-CAT-02 | B14: "No content yet" message for categories with no data is not visible the existing message is false | C14: user is logged in | D14: for admin: userName: 'admin', email: 'admin@learninghub.com', password: 'Admin@123', for user: userName: 'user1', email: 'user1@learninghub.com', password: 'User@123', | E14: 1-Click on a category that has no articles or videos | G14: "No content yet" message for categories with no data should be displayed | H14: "No Video" message for categories with no data is displayed False message | J14: Low | K14: Medium | L14: Low | M14: =LET( total_score, SUM( SWITCH(J14, "High", 3, "Medium", 2, "Low", 1, 0), SWITCH(K14, "High", 3, "Medium", 2, "Low", 1, 0), SWITCH(L14, "High", 3, "Medium", 2, "Low", 1, 0) ), IFS( total_score >= 8, "Critical", total_score >= 5, "Major", total_score < 5, "Minor" )) -> Minor | N14: TC-CAT-03 | O14: Closed | P14: SRS_Category_03 | Q14: yara
J15: Medium | K15: High | L15: Low | M15: =LET( total_score, SUM( SWITCH(J15, "High", 3, "Medium", 2, "Low", 1, 0), SWITCH(K15, "High", 3, "Medium", 2, "Low", 1, 0), SWITCH(L15, "High", 3, "Medium", 2, "Low", 1, 0) ), IFS( total_score >= 8, "Critical", total_score >= 5, "Major", total_score < 5, "Minor" )) -> Major
J16: Medium | K16: High | L16: Low | M16: =LET( total_score, SUM( SWITCH(J16, "High", 3, "Medium", 2, "Low", 1, 0), SWITCH(K16, "High", 3, "Medium", 2, "Low", 1, 0), SWITCH(L16, "High", 3, "Medium", 2, "Low", 1, 0) ), IFS( total_score >= 8, "Critical", total_score >= 5, "Major", total_score < 5, "Minor" )) -> Major

Sheet Summary Report v1
A1: Execution
A2: Number of TCs | B2: passed | C2: failed | D2: blocked | E2: not executed
A3: =COUNTA('Execution V1'!A2:A117) -> 43 | B3: =COUNTIF('Execution V1'!O:O,"Pass") -> 22 | C3: =COUNTIF('Execution V1'!O:O,"Fail") -> 9 | D3: =COUNTIF('Execution V1'!O:O,"blocked") -> 12 | E3: =COUNTIF('Execution V1'!O:O,"Not executed") -> 0
A4: percentage % | B4: =B3/A3% -> 51.162791 | C4: =C3/A3% -> 20.930233 | D4: =D3/A3% -> 27.906977 | E4: =E3/A3% -> 0
A6: BUGs
B7: Opened | C7: New | D7: Fixed | E7: Retest | F7: Reopened | G7: Closed
A8: Count | B8: =countif('Bug Report V1'!O:O,"Open") -> 0 | C8: =countif('Bug Report V1'!O:O,"New") -> 0 | D8: =countif('Bug Report V1'!O:O,"Fix") -> 0 | E8: =countif('Bug Report V1'!O:O,"Retest") -> 0 | F8: =countif('Bug Report V1'!O:O,"Reopen") -> 0 | G8: =countif('Bug Report V1'!O:O,"Closed") -> 13

Sheet Execution V2
A1: TesTCASE ID | B1: Test Cases Title / Objective | C1: Env | D1: Pre-condition | E1: Steps | F1: Test Data | G1: Expected Results | H1: Post Cond | I1: TC Status | J1: Valid\invalid | K1: Attachment | L1: Requirement ID | M1: Type | N1: Tester | O1: Execution Status
A2: TC_SIGNUP_001 | B2: Verify user can register with valid inputs | C2: Chrome v27+ | D2: Open the URL: User is on Sign Up page | E2: Create User account : 1- Enter username 2- enter email (20–50 chars) 3- Enter password (more than 8 less than 16) 4- Click Sign Up Delete the created account : 5- signup with admin account 6- go to manage users 7- press delete account | F2: 1- Username: yaranasser 2- Email: yaranasser1665@gmail.com 3- Password: 0123456@Yara | G2: User is registered successfully and redirected to Home page | H2: Account is created User is redirected to Home page Delete the created account | I2: Pass | J2: Valid | L2: SRS_SignUp_001 SRS_SignUp_011 | M2: Functional | N2: yara | O2: Pass
A3: TC_SIGNUP_002 | B3: Check username placeholder exists | C3: Chrome v27+ | D3: Open the URL: User is on Sign Up page | E3: 1- Navigate to Sign Up page 2- Observe Username field | F3: N/A | G3: Username field displays a placeholder (e.g., "Choose a username (letters,numbers,spaces,special chars)") | H3: Field remains unchanged | I3: Pass | J3: Valid | L3: SRS_SignUp_002 | M3: UI | N3: yara | O3: Pass
A4: TC_SIGNUP_003 | B4: Verify username is unique | C4: Chrome v27+ | D4: Open the URL: User is on Sign Up page | E4: 1- Enter used username 2- enter email (20–50 chars) 3- Enter password (8–16 chars with uppercase & special char) 4- Click Sign Up | F4: 1- Username: yaranasser 2- Email: yaranasser123@gmail.com 3- Password: 0147852@Yara | G4: User is can't register and and error message appears "Username already taken." | H4: Account is not created User remains in the signup page | I4: Pass | J4: Valid | L4: SRS_SignUp_003 | M4: Functional | N4: yara | O4: Pass
A5: TC_SIGNUP_004 | B5: Verify username accepts special characters | C5: Chrome v27+ | D5: Open the URL: User is on Sign Up page | E5: Create User account : 1- Enter username 2- enter email (20–50 chars) 3- Enter password (more than 8 less than 16) 4- Click Sign Up Delete the created account : 5- signup with admin account 6- go to manage users 7- press delete account | F5: User account 1- Username:yara@ 2- Email: yaranasser123@gmail.com 3- Password: 0123456@Yara Admin account 1- admin 2- Admin@123 | G5: System accepts username and completes registration | H5: Account is created User is redirected to Home page Delete the created account : - signup with admin account - go to manage users - press delete account | I5: Pass | J5: Valid | L5: SRS_SignUp_004 | M5: Functional | N5: yara | O5: Pass
A6: TC_SIGNUP_005 | B6: Verify username accepts numbers | C6: Chrome v27+ | D6: Open the URL: User is on Sign Up page | E6: Create User account : 1- Enter username 2- enter email (20–50 chars) 3- Enter password (more than 8 less than 16) 4- Click Sign Up Delete the created account : 5- signup with admin account 6- go to manage users 7- press delete account | F6: User account 1- Username:yara123 2- Email: yaranasser123@gmail.com 3- Password: 0123456@Yara Admin account 1- admin 2- Admin@123 | G6: System accepts username and completes registration | H6: Account is created User is redirected to Home page Delete the created account : - signup with admin account - go to manage users - press delete account | I6: Pass | J6: Valid | L6: SRS_SignUp_005 | M6: Functional | N6: yara | O6: Pass
A7: TC_SIGNUP_006 | B7: Verify username accepts spaces | C7: Chrome v27+ | D7: Open the URL: User is on Sign Up page | E7: Create User account : 1- Enter username 2- enter email (20–50 chars) 3- Enter password (more than 8 less than 16) 4- Click Sign Up Delete the created account : 5- signup with admin account 6- go to manage users 7- press delete account | F7: User account 1- Username:yara ynn 2- Email: yaranasser123@gmail.com 3- Password: 0123456@Yara Admin account 1- admin 2- Admin@123 | G7: System accepts username with spaces | H7: Account is created User is redirected to Home page Delete the created account : - signup with admin account - go to manage users - press delete account | I7: Pass | J7: Valid | L7: SRS_SignUp_006 | M7: Functional | N7: yara | O7: Pass
A8: TC_SIGNUP_007 | B8: Verify valid email length when it is between 20 and 50 characters | C8: Chrome v27+ | D8: Open the URL: User is on Sign Up page | E8: Create User account : 1- Enter username 2- enter email (20–50 chars) 3- Enter password (more than 8 less than 16) 4- Click Sign Up Delete the created account : 5- signup with admin account 6- go to manage users 7- press delete account | F8: User account 1- Username:yaranasser 2- Email: yaranasser123@gmail.com 3- Password: 0123456@Yara Admin account 1- admin 2- Admin@123 | G8: System accepts inputs data and directed to the home page | H8: Account is created User is redirected to Home page Delete the created account : - signup with admin account - go to manage users - press delete account | I8: Pass | J8: Valid | L8: SRS_SignUp_007 | M8: Functional | N8: yara | O8: Pass
A9: TC_SIGNUP_008 | B9: Verify invalid email length when it is more than 50 characters | C9: Chrome v27+ | D9: Open the URL: User is on Sign Up page | E9: 1- Enter username 2- enter email (more than 50) 3- Enter password (8–16 chars with uppercase & special char) 4- Click Sign Up | F9: User account 1- Username:yaranasserr 2- Email: yaranasseryaranasser166666666666666666666665@gmail.com@gmail.com 3- Password: 0123456@Yara | G9: System rejects both inputs and shows error("Email must not exceed 50 characters") | H9: Account is NOT created User remains on Sign Up page Error message is displayed | I9: Pass | J9: Invalid | L9: SRS_SignUp_007 | M9: Functional | N9: yara | O9: Pass
A10: TC_SIGNUP_009 | B10: Verify invalid email length when it is less than 20 characters | C10: Chrome v27+ | D10: Open the URL: User is on Sign Up page | E10: 1- Enter username 2- enter email (less than 20) 3- Enter password (8–16 chars with uppercase & special char) 4- Click Sign Up | F10: User account 1- Username:yaranasserr 2- Email: yn@gmail.com 3- Password: 0123456@Yara | G10: System rejects both inputs and shows error("Email must be at least 20 characters") | H10: Account is NOT created User remains on Sign Up page Error message is displayed | I10: Pass | J10: Invalid | L10: SRS_SignUp_007 | M10: Functional | N10: yara | O10: Pass
A11: TC_SIGNUP_010 | B11: Verify valid password length when it is more than 8 and less than 16 characters | C11: Chrome v27+ | D11: Open the URL: User is on Sign Up page | E11: Create User account : 1- Enter username 2- enter email (20–50 chars) 3- Enter password (more than 8 less than 16) 4- Click Sign Up Delete the created account : 5- signup with admin account 6- go to manage users 7- press delete account | F11: User account 1- Username:yaranasser 2- Email: yaranasser123@gmail.com 3- Password: 0123456@Yara Admin account 1- admin 2- Admin@123 | G11: System accepts valid lengths Account is created User directed to home page | H11: Account is created User is redirected to Home page Delete the created account | I11: Pass | J11: Valid | L11: SRS_SignUp_008 | M11: Functional | N11: yara | O11: Pass
